test
INFO:unittestLogger:Executing test setup...
INFO:unittestLogger:Test setup complete. Executing test...
INFO:unittestLogger:Executing test setup...
INFO:unittestLogger:Test setup complete. Executing test...
INFO:unittestLogger:Test execution complete. Running cleanup...
ERROR:unittestLogger:<Test Result: Test Failed>
INFO:unittestLogger:Executing test setup...
INFO:unittestLogger:Executing test setup...
INFO:unittestLogger:Test setup complete. Executing test...
INFO:unittestLogger:Test execution complete. Running cleanup...
INFO:unittestLogger:<Test Result: Test Passed>
ERROR:unittestLogger:
Traceback (most recent call last):
  File "C:\Users\czhao\git_root\dtaf\czhao_coverage\src\dtaf_core\lib\base_test_case.py", line 182, in main
    tester.prepare()
  File "c:\program files\python38\lib\unittest\mock.py", line 1081, in __call__
    return self._mock_call(*args, **kwargs)
  File "c:\program files\python38\lib\unittest\mock.py", line 1085, in _mock_call
    return self._execute_mock_call(*args, **kwargs)
  File "c:\program files\python38\lib\unittest\mock.py", line 1140, in _execute_mock_call
    raise effect
RuntimeError
INFO:unittestLogger:Test preparation failed. Running cleanup...
ERROR:unittestLogger:<Test Result: Test Failed>
ERROR:unittestLogger:
Traceback (most recent call last):
  File "C:\Users\czhao\git_root\dtaf\czhao_coverage\src\dtaf_core\lib\base_test_case.py", line 195, in main
    test_result = tester.execute()
  File "c:\program files\python38\lib\unittest\mock.py", line 1081, in __call__
    return self._mock_call(*args, **kwargs)
  File "c:\program files\python38\lib\unittest\mock.py", line 1085, in _mock_call
    return self._execute_mock_call(*args, **kwargs)
  File "c:\program files\python38\lib\unittest\mock.py", line 1140, in _execute_mock_call
    raise effect
RuntimeError
INFO:unittestLogger:Test execution complete. Running cleanup...
ERROR:unittestLogger:<Test Result: Test Failed>
INFO:unittestLogger:Executing test setup...
INFO:unittestLogger:Test setup complete. Executing test...
INFO:unittestLogger:Test execution complete. Running cleanup...
ERROR:unittestLogger:<Test Result: Test Failed>
ERROR:root:Traceback (most recent call last):
  File "C:\Users\czhao\git_root\dtaf\czhao_coverage\src\dtaf_core\providers\internal\ssh_sut_os_provider.py", line 149, in execute
    exec_result = target.run(cmd, hide=True, warn=True, timeout=timeout,
  File "c:\program files\python38\lib\unittest\mock.py", line 1081, in __call__
    return self._mock_call(*args, **kwargs)
  File "c:\program files\python38\lib\unittest\mock.py", line 1085, in _mock_call
    return self._execute_mock_call(*args, **kwargs)
  File "c:\program files\python38\lib\unittest\mock.py", line 1140, in _execute_mock_call
    raise effect
paramiko.ssh_exception.SSHException
Traceback (most recent call last):
  File "C:\Users\czhao\git_root\dtaf\czhao_coverage\src\dtaf_core\providers\internal\ssh_sut_os_provider.py", line 149, in execute
    exec_result = target.run(cmd, hide=True, warn=True, timeout=timeout,
  File "c:\program files\python38\lib\unittest\mock.py", line 1081, in __call__
    return self._mock_call(*args, **kwargs)
  File "c:\program files\python38\lib\unittest\mock.py", line 1085, in _mock_call
    return self._execute_mock_call(*args, **kwargs)
  File "c:\program files\python38\lib\unittest\mock.py", line 1140, in _execute_mock_call
    raise effect
paramiko.ssh_exception.SSHException
ERROR:root:Traceback (most recent call last):
  File "C:\Users\czhao\git_root\dtaf\czhao_coverage\src\dtaf_core\providers\internal\ssh_sut_os_provider.py", line 149, in execute
    exec_result = target.run(cmd, hide=True, warn=True, timeout=timeout,
  File "c:\program files\python38\lib\unittest\mock.py", line 1081, in __call__
    return self._mock_call(*args, **kwargs)
  File "c:\program files\python38\lib\unittest\mock.py", line 1085, in _mock_call
    return self._execute_mock_call(*args, **kwargs)
  File "c:\program files\python38\lib\unittest\mock.py", line 1140, in _execute_mock_call
    raise effect
OSError
Traceback (most recent call last):
  File "C:\Users\czhao\git_root\dtaf\czhao_coverage\src\dtaf_core\providers\internal\ssh_sut_os_provider.py", line 149, in execute
    exec_result = target.run(cmd, hide=True, warn=True, timeout=timeout,
  File "c:\program files\python38\lib\unittest\mock.py", line 1081, in __call__
    return self._mock_call(*args, **kwargs)
  File "c:\program files\python38\lib\unittest\mock.py", line 1085, in _mock_call
    return self._execute_mock_call(*args, **kwargs)
  File "c:\program files\python38\lib\unittest\mock.py", line 1140, in _execute_mock_call
    raise effect
OSError
ERROR:root:Traceback (most recent call last):
  File "C:\Users\czhao\git_root\dtaf\czhao_coverage\src\dtaf_core\providers\internal\ssh_sut_os_provider.py", line 149, in execute
    exec_result = target.run(cmd, hide=True, warn=True, timeout=timeout,
  File "c:\program files\python38\lib\unittest\mock.py", line 1081, in __call__
    return self._mock_call(*args, **kwargs)
  File "c:\program files\python38\lib\unittest\mock.py", line 1085, in _mock_call
    return self._execute_mock_call(*args, **kwargs)
  File "c:\program files\python38\lib\unittest\mock.py", line 1140, in _execute_mock_call
    raise effect
RuntimeError
Traceback (most recent call last):
  File "C:\Users\czhao\git_root\dtaf\czhao_coverage\src\dtaf_core\providers\internal\ssh_sut_os_provider.py", line 149, in execute
    exec_result = target.run(cmd, hide=True, warn=True, timeout=timeout,
  File "c:\program files\python38\lib\unittest\mock.py", line 1081, in __call__
    return self._mock_call(*args, **kwargs)
  File "c:\program files\python38\lib\unittest\mock.py", line 1085, in _mock_call
    return self._execute_mock_call(*args, **kwargs)
  File "c:\program files\python38\lib\unittest\mock.py", line 1140, in _execute_mock_call
    raise effect
RuntimeError
ERROR:root:Traceback (most recent call last):
  File "C:\Users\czhao\git_root\dtaf\czhao_coverage\src\dtaf_core\providers\internal\ssh_sut_os_provider.py", line 149, in execute
    exec_result = target.run(cmd, hide=True, warn=True, timeout=timeout,
  File "c:\program files\python38\lib\unittest\mock.py", line 1081, in __call__
    return self._mock_call(*args, **kwargs)
  File "c:\program files\python38\lib\unittest\mock.py", line 1085, in _mock_call
    return self._execute_mock_call(*args, **kwargs)
  File "c:\program files\python38\lib\unittest\mock.py", line 1140, in _execute_mock_call
    raise effect
ArithmeticError
Traceback (most recent call last):
  File "C:\Users\czhao\git_root\dtaf\czhao_coverage\src\dtaf_core\providers\internal\ssh_sut_os_provider.py", line 149, in execute
    exec_result = target.run(cmd, hide=True, warn=True, timeout=timeout,
  File "c:\program files\python38\lib\unittest\mock.py", line 1081, in __call__
    return self._mock_call(*args, **kwargs)
  File "c:\program files\python38\lib\unittest\mock.py", line 1085, in _mock_call
    return self._execute_mock_call(*args, **kwargs)
  File "c:\program files\python38\lib\unittest\mock.py", line 1140, in _execute_mock_call
    raise effect
ArithmeticError
ERROR:root:Traceback (most recent call last):
  File "C:\Users\czhao\git_root\dtaf\czhao_coverage\src\dtaf_core\providers\internal\ssh_sut_os_provider.py", line 149, in execute
    exec_result = target.run(cmd, hide=True, warn=True, timeout=timeout,
  File "c:\program files\python38\lib\unittest\mock.py", line 1081, in __call__
    return self._mock_call(*args, **kwargs)
  File "c:\program files\python38\lib\unittest\mock.py", line 1085, in _mock_call
    return self._execute_mock_call(*args, **kwargs)
  File "c:\program files\python38\lib\unittest\mock.py", line 1140, in _execute_mock_call
    raise effect
ValueError
Traceback (most recent call last):
  File "C:\Users\czhao\git_root\dtaf\czhao_coverage\src\dtaf_core\providers\internal\ssh_sut_os_provider.py", line 149, in execute
    exec_result = target.run(cmd, hide=True, warn=True, timeout=timeout,
  File "c:\program files\python38\lib\unittest\mock.py", line 1081, in __call__
    return self._mock_call(*args, **kwargs)
  File "c:\program files\python38\lib\unittest\mock.py", line 1085, in _mock_call
    return self._execute_mock_call(*args, **kwargs)
  File "c:\program files\python38\lib\unittest\mock.py", line 1140, in _execute_mock_call
    raise effect
ValueError
ERROR:root:Traceback (most recent call last):
  File "C:\Users\czhao\git_root\dtaf\czhao_coverage\src\dtaf_core\providers\internal\ssh_sut_os_provider.py", line 149, in execute
    exec_result = target.run(cmd, hide=True, warn=True, timeout=timeout,
  File "c:\program files\python38\lib\unittest\mock.py", line 1081, in __call__
    return self._mock_call(*args, **kwargs)
  File "c:\program files\python38\lib\unittest\mock.py", line 1085, in _mock_call
    return self._execute_mock_call(*args, **kwargs)
  File "c:\program files\python38\lib\unittest\mock.py", line 1140, in _execute_mock_call
    raise effect
KeyError
Traceback (most recent call last):
  File "C:\Users\czhao\git_root\dtaf\czhao_coverage\src\dtaf_core\providers\internal\ssh_sut_os_provider.py", line 149, in execute
    exec_result = target.run(cmd, hide=True, warn=True, timeout=timeout,
  File "c:\program files\python38\lib\unittest\mock.py", line 1081, in __call__
    return self._mock_call(*args, **kwargs)
  File "c:\program files\python38\lib\unittest\mock.py", line 1085, in _mock_call
    return self._execute_mock_call(*args, **kwargs)
  File "c:\program files\python38\lib\unittest\mock.py", line 1140, in _execute_mock_call
    raise effect
KeyError
ERROR:root:CPUID values were not consistent across threads!
NoneType: None
ERROR:root:CPUID Reg eax Leaf 2 Subleaf None: [912559, 64206, 912559, 64206, 912559, 64206, 912559, 64206, 912559, 64206, 912559, 64206]
NoneType: None
ERROR:root:Write to memory address 0x100p failed!  Expected 912559 Actual: 3735928559
NoneType: None
ERROR:root:No MSR values received! Please check the ITP setup.
NoneType: None
ERROR:root:No MSR values received! Please check the ITP setup.
NoneType: None
ERROR:root:MSR values were not consistent across threads!
NoneType: None
ERROR:root:MSR 314: [64206, 912559, 64206, 912559, 64206, 912559, 64206, 912559, 64206, 912559, 64206, 912559, 64206, 912559, 64206, 912559, 64206, 912559, 64206, 912559, 64206, 912559, 64206, 912559]
NoneType: None
ERROR:root:MSR values were not consistent across threads!
NoneType: None
ERROR:root:MSR 6: [912559, 912559, 912559, 912559, 912559, 912559, 912559, 912559, 912559, 912559, 912559, 912559, 912559, 912559, 912559, 912559, 912559, 912559, 912559, 912559, 912559, 912559, 912559, 64206]
NoneType: None
ERROR:root:Write to MSR address 6 failed! Threads had varying values: ('MSR values were not consistent across threads!', [912559, 912559, 912559, 912559, 912559, 912559, 912559, 912559, 912559, 912559, 912559, 912559, 912559, 912559, 912559, 912559, 912559, 912559, 912559, 912559, 912559, 912559, 912559, 64206])
Traceback (most recent call last):
  File "C:\Users\czhao\git_root\dtaf\czhao_coverage\src\dtaf_core\providers\internal\xdp_silicon_debug_provider.py", line 190, in msr_write
    read_back = self.msr_read(msr_address, thread=thread, squash=True)
  File "C:\Users\czhao\git_root\dtaf\czhao_coverage\src\dtaf_core\providers\internal\xdp_silicon_debug_provider.py", line 173, in msr_read
    raise RegisterInconsistencyException("MSR values were not consistent across threads!", msr_values)
dtaf_core.lib.exceptions.RegisterInconsistencyException: ('MSR values were not consistent across threads!', [912559, 912559, 912559, 912559, 912559, 912559, 912559, 912559, 912559, 912559, 912559, 912559, 912559, 912559, 912559, 912559, 912559, 912559, 912559, 912559, 912559, 912559, 912559, 64206])
ERROR:root:Write to MSR address 6 failed! Expected: 912559 Actual: 64206
NoneType: None
ERROR:root:MSR values were not consistent across threads!
NoneType: None
ERROR:root:MSR 6: [912559, 912559, 912559, 912559, 912559, 912559, 912559, 912559, 912559, 912559, 912559, 912559, 912559, 912559, 912559, 912559, 912559, 912559, 912559, 912559, 912559, 912559, 912559, 64206]
NoneType: None
ERROR:root:Write to MSR address 6 failed! Threads had varying values: ('MSR values were not consistent across threads!', [912559, 912559, 912559, 912559, 912559, 912559, 912559, 912559, 912559, 912559, 912559, 912559, 912559, 912559, 912559, 912559, 912559, 912559, 912559, 912559, 912559, 912559, 912559, 64206])
Traceback (most recent call last):
  File "C:\Users\czhao\git_root\dtaf\czhao_coverage\src\dtaf_core\providers\internal\xdp_silicon_debug_provider.py", line 190, in msr_write
    read_back = self.msr_read(msr_address, thread=thread, squash=True)
  File "C:\Users\czhao\git_root\dtaf\czhao_coverage\src\dtaf_core\providers\internal\xdp_silicon_debug_provider.py", line 173, in msr_read
    raise RegisterInconsistencyException("MSR values were not consistent across threads!", msr_values)
dtaf_core.lib.exceptions.RegisterInconsistencyException: ('MSR values were not consistent across threads!', [912559, 912559, 912559, 912559, 912559, 912559, 912559, 912559, 912559, 912559, 912559, 912559, 912559, 912559, 912559, 912559, 912559, 912559, 912559, 912559, 912559, 912559, 912559, 64206])
INFO:unittestLogger:Executing test setup...
INFO:unittestLogger:Test setup complete. Executing test...
INFO:unittestLogger:Test execution complete. Running cleanup...
ERROR:unittestLogger:<Test Result: Test Failed>
INFO:unittestLogger:Executing test setup...
INFO:unittestLogger:Test setup complete. Executing test...
ERROR:unittestLogger:
Traceback (most recent call last):
  File "C:\Users\czhao\git_root\dtaf\czhao_coverage\src\dtaf_core\lib\base_test_case.py", line 195, in main
    test_result = tester.execute()
  File "c:\program files\python38\lib\unittest\mock.py", line 1081, in __call__
    return self._mock_call(*args, **kwargs)
  File "c:\program files\python38\lib\unittest\mock.py", line 1085, in _mock_call
    return self._execute_mock_call(*args, **kwargs)
  File "c:\program files\python38\lib\unittest\mock.py", line 1140, in _execute_mock_call
    raise effect
RuntimeError
INFO:unittestLogger:Test execution complete. Running cleanup...
ERROR:unittestLogger:<Test Result: Test Failed>
INFO:unittestLogger:Executing test setup...
INFO:unittestLogger:Test setup complete. Executing test...
INFO:unittestLogger:Test execution complete. Running cleanup...
ERROR:unittestLogger:<Test Result: Test Failed>
INFO:unittestLogger:Executing test setup...
ERROR:unittestLogger:
Traceback (most recent call last):
  File "C:\Users\czhao\git_root\dtaf\czhao_coverage\src\dtaf_core\lib\base_test_case.py", line 182, in main
    tester.prepare()
  File "c:\program files\python38\lib\unittest\mock.py", line 1081, in __call__
    return self._mock_call(*args, **kwargs)
  File "c:\program files\python38\lib\unittest\mock.py", line 1085, in _mock_call
    return self._execute_mock_call(*args, **kwargs)
  File "c:\program files\python38\lib\unittest\mock.py", line 1140, in _execute_mock_call
    raise effect
RuntimeError
INFO:unittestLogger:Test preparation failed. Running cleanup...
ERROR:unittestLogger:<Test Result: Test Failed>
INFO:unittestLogger:Executing test setup...
INFO:unittestLogger:Test setup complete. Executing test...
INFO:unittestLogger:Test execution complete. Running cleanup...
INFO:unittestLogger:<Test Result: Test Passed>
ERROR:root:Traceback (most recent call last):
  File "C:\Users\czhao\git_root\dtaf\czhao_coverage\src\dtaf_core\providers\internal\ssh_sut_os_provider.py", line 149, in execute
    exec_result = target.run(cmd, hide=True, warn=True, timeout=timeout,
  File "c:\program files\python38\lib\unittest\mock.py", line 1081, in __call__
    return self._mock_call(*args, **kwargs)
  File "c:\program files\python38\lib\unittest\mock.py", line 1085, in _mock_call
    return self._execute_mock_call(*args, **kwargs)
  File "c:\program files\python38\lib\unittest\mock.py", line 1140, in _execute_mock_call
    raise effect
paramiko.ssh_exception.SSHException
Traceback (most recent call last):
  File "C:\Users\czhao\git_root\dtaf\czhao_coverage\src\dtaf_core\providers\internal\ssh_sut_os_provider.py", line 149, in execute
    exec_result = target.run(cmd, hide=True, warn=True, timeout=timeout,
  File "c:\program files\python38\lib\unittest\mock.py", line 1081, in __call__
    return self._mock_call(*args, **kwargs)
  File "c:\program files\python38\lib\unittest\mock.py", line 1085, in _mock_call
    return self._execute_mock_call(*args, **kwargs)
  File "c:\program files\python38\lib\unittest\mock.py", line 1140, in _execute_mock_call
    raise effect
paramiko.ssh_exception.SSHException
ERROR:root:Traceback (most recent call last):
  File "C:\Users\czhao\git_root\dtaf\czhao_coverage\src\dtaf_core\providers\internal\ssh_sut_os_provider.py", line 149, in execute
    exec_result = target.run(cmd, hide=True, warn=True, timeout=timeout,
  File "c:\program files\python38\lib\unittest\mock.py", line 1081, in __call__
    return self._mock_call(*args, **kwargs)
  File "c:\program files\python38\lib\unittest\mock.py", line 1085, in _mock_call
    return self._execute_mock_call(*args, **kwargs)
  File "c:\program files\python38\lib\unittest\mock.py", line 1140, in _execute_mock_call
    raise effect
OSError
Traceback (most recent call last):
  File "C:\Users\czhao\git_root\dtaf\czhao_coverage\src\dtaf_core\providers\internal\ssh_sut_os_provider.py", line 149, in execute
    exec_result = target.run(cmd, hide=True, warn=True, timeout=timeout,
  File "c:\program files\python38\lib\unittest\mock.py", line 1081, in __call__
    return self._mock_call(*args, **kwargs)
  File "c:\program files\python38\lib\unittest\mock.py", line 1085, in _mock_call
    return self._execute_mock_call(*args, **kwargs)
  File "c:\program files\python38\lib\unittest\mock.py", line 1140, in _execute_mock_call
    raise effect
OSError
ERROR:root:Traceback (most recent call last):
  File "C:\Users\czhao\git_root\dtaf\czhao_coverage\src\dtaf_core\providers\internal\ssh_sut_os_provider.py", line 149, in execute
    exec_result = target.run(cmd, hide=True, warn=True, timeout=timeout,
  File "c:\program files\python38\lib\unittest\mock.py", line 1081, in __call__
    return self._mock_call(*args, **kwargs)
  File "c:\program files\python38\lib\unittest\mock.py", line 1085, in _mock_call
    return self._execute_mock_call(*args, **kwargs)
  File "c:\program files\python38\lib\unittest\mock.py", line 1140, in _execute_mock_call
    raise effect
RuntimeError
Traceback (most recent call last):
  File "C:\Users\czhao\git_root\dtaf\czhao_coverage\src\dtaf_core\providers\internal\ssh_sut_os_provider.py", line 149, in execute
    exec_result = target.run(cmd, hide=True, warn=True, timeout=timeout,
  File "c:\program files\python38\lib\unittest\mock.py", line 1081, in __call__
    return self._mock_call(*args, **kwargs)
  File "c:\program files\python38\lib\unittest\mock.py", line 1085, in _mock_call
    return self._execute_mock_call(*args, **kwargs)
  File "c:\program files\python38\lib\unittest\mock.py", line 1140, in _execute_mock_call
    raise effect
RuntimeError
ERROR:root:Traceback (most recent call last):
  File "C:\Users\czhao\git_root\dtaf\czhao_coverage\src\dtaf_core\providers\internal\ssh_sut_os_provider.py", line 149, in execute
    exec_result = target.run(cmd, hide=True, warn=True, timeout=timeout,
  File "c:\program files\python38\lib\unittest\mock.py", line 1081, in __call__
    return self._mock_call(*args, **kwargs)
  File "c:\program files\python38\lib\unittest\mock.py", line 1085, in _mock_call
    return self._execute_mock_call(*args, **kwargs)
  File "c:\program files\python38\lib\unittest\mock.py", line 1140, in _execute_mock_call
    raise effect
ArithmeticError
Traceback (most recent call last):
  File "C:\Users\czhao\git_root\dtaf\czhao_coverage\src\dtaf_core\providers\internal\ssh_sut_os_provider.py", line 149, in execute
    exec_result = target.run(cmd, hide=True, warn=True, timeout=timeout,
  File "c:\program files\python38\lib\unittest\mock.py", line 1081, in __call__
    return self._mock_call(*args, **kwargs)
  File "c:\program files\python38\lib\unittest\mock.py", line 1085, in _mock_call
    return self._execute_mock_call(*args, **kwargs)
  File "c:\program files\python38\lib\unittest\mock.py", line 1140, in _execute_mock_call
    raise effect
ArithmeticError
ERROR:root:Traceback (most recent call last):
  File "C:\Users\czhao\git_root\dtaf\czhao_coverage\src\dtaf_core\providers\internal\ssh_sut_os_provider.py", line 149, in execute
    exec_result = target.run(cmd, hide=True, warn=True, timeout=timeout,
  File "c:\program files\python38\lib\unittest\mock.py", line 1081, in __call__
    return self._mock_call(*args, **kwargs)
  File "c:\program files\python38\lib\unittest\mock.py", line 1085, in _mock_call
    return self._execute_mock_call(*args, **kwargs)
  File "c:\program files\python38\lib\unittest\mock.py", line 1140, in _execute_mock_call
    raise effect
ValueError
Traceback (most recent call last):
  File "C:\Users\czhao\git_root\dtaf\czhao_coverage\src\dtaf_core\providers\internal\ssh_sut_os_provider.py", line 149, in execute
    exec_result = target.run(cmd, hide=True, warn=True, timeout=timeout,
  File "c:\program files\python38\lib\unittest\mock.py", line 1081, in __call__
    return self._mock_call(*args, **kwargs)
  File "c:\program files\python38\lib\unittest\mock.py", line 1085, in _mock_call
    return self._execute_mock_call(*args, **kwargs)
  File "c:\program files\python38\lib\unittest\mock.py", line 1140, in _execute_mock_call
    raise effect
ValueError
ERROR:root:Traceback (most recent call last):
  File "C:\Users\czhao\git_root\dtaf\czhao_coverage\src\dtaf_core\providers\internal\ssh_sut_os_provider.py", line 149, in execute
    exec_result = target.run(cmd, hide=True, warn=True, timeout=timeout,
  File "c:\program files\python38\lib\unittest\mock.py", line 1081, in __call__
    return self._mock_call(*args, **kwargs)
  File "c:\program files\python38\lib\unittest\mock.py", line 1085, in _mock_call
    return self._execute_mock_call(*args, **kwargs)
  File "c:\program files\python38\lib\unittest\mock.py", line 1140, in _execute_mock_call
    raise effect
KeyError
Traceback (most recent call last):
  File "C:\Users\czhao\git_root\dtaf\czhao_coverage\src\dtaf_core\providers\internal\ssh_sut_os_provider.py", line 149, in execute
    exec_result = target.run(cmd, hide=True, warn=True, timeout=timeout,
  File "c:\program files\python38\lib\unittest\mock.py", line 1081, in __call__
    return self._mock_call(*args, **kwargs)
  File "c:\program files\python38\lib\unittest\mock.py", line 1085, in _mock_call
    return self._execute_mock_call(*args, **kwargs)
  File "c:\program files\python38\lib\unittest\mock.py", line 1140, in _execute_mock_call
    raise effect
KeyError
ERROR:root:CPUID values were not consistent across threads!
NoneType: None
ERROR:root:CPUID Reg eax Leaf 2 Subleaf None: [912559, 64206, 912559, 64206, 912559, 64206, 912559, 64206, 912559, 64206, 912559, 64206]
NoneType: None
ERROR:root:No MSR values received! Please check the ITP setup.
NoneType: None
ERROR:root:No MSR values received! Please check the ITP setup.
NoneType: None
ERROR:root:MSR values were not consistent across threads!
NoneType: None
ERROR:root:MSR 314: [64206, 912559, 64206, 912559, 64206, 912559, 64206, 912559, 64206, 912559, 64206, 912559, 64206, 912559, 64206, 912559, 64206, 912559, 64206, 912559, 64206, 912559, 64206, 912559]
NoneType: None
ERROR:root:Write to memory address 0x100p failed!  Expected 912559 Actual: 3735928559
NoneType: None
ERROR:root:Write to MSR address 6 failed! Expected: 912559 Actual: 64206
NoneType: None
ERROR:root:MSR values were not consistent across threads!
NoneType: None
ERROR:root:MSR 6: [912559, 912559, 912559, 912559, 912559, 912559, 912559, 912559, 912559, 912559, 912559, 912559, 912559, 912559, 912559, 912559, 912559, 912559, 912559, 912559, 912559, 912559, 912559, 64206]
NoneType: None
ERROR:root:Write to MSR address 6 failed! Threads had varying values: ('MSR values were not consistent across threads!', [912559, 912559, 912559, 912559, 912559, 912559, 912559, 912559, 912559, 912559, 912559, 912559, 912559, 912559, 912559, 912559, 912559, 912559, 912559, 912559, 912559, 912559, 912559, 64206])
Traceback (most recent call last):
  File "C:\Users\czhao\git_root\dtaf\czhao_coverage\src\dtaf_core\providers\internal\xdp_silicon_debug_provider.py", line 190, in msr_write
    read_back = self.msr_read(msr_address, thread=thread, squash=True)
  File "C:\Users\czhao\git_root\dtaf\czhao_coverage\src\dtaf_core\providers\internal\xdp_silicon_debug_provider.py", line 173, in msr_read
    raise RegisterInconsistencyException("MSR values were not consistent across threads!", msr_values)
dtaf_core.lib.exceptions.RegisterInconsistencyException: ('MSR values were not consistent across threads!', [912559, 912559, 912559, 912559, 912559, 912559, 912559, 912559, 912559, 912559, 912559, 912559, 912559, 912559, 912559, 912559, 912559, 912559, 912559, 912559, 912559, 912559, 912559, 64206])
ERROR:root:MSR values were not consistent across threads!
NoneType: None
ERROR:root:MSR 6: [912559, 912559, 912559, 912559, 912559, 912559, 912559, 912559, 912559, 912559, 912559, 912559, 912559, 912559, 912559, 912559, 912559, 912559, 912559, 912559, 912559, 912559, 912559, 64206]
NoneType: None
ERROR:root:Write to MSR address 6 failed! Threads had varying values: ('MSR values were not consistent across threads!', [912559, 912559, 912559, 912559, 912559, 912559, 912559, 912559, 912559, 912559, 912559, 912559, 912559, 912559, 912559, 912559, 912559, 912559, 912559, 912559, 912559, 912559, 912559, 64206])
Traceback (most recent call last):
  File "C:\Users\czhao\git_root\dtaf\czhao_coverage\src\dtaf_core\providers\internal\xdp_silicon_debug_provider.py", line 190, in msr_write
    read_back = self.msr_read(msr_address, thread=thread, squash=True)
  File "C:\Users\czhao\git_root\dtaf\czhao_coverage\src\dtaf_core\providers\internal\xdp_silicon_debug_provider.py", line 173, in msr_read
    raise RegisterInconsistencyException("MSR values were not consistent across threads!", msr_values)
dtaf_core.lib.exceptions.RegisterInconsistencyException: ('MSR values were not consistent across threads!', [912559, 912559, 912559, 912559, 912559, 912559, 912559, 912559, 912559, 912559, 912559, 912559, 912559, 912559, 912559, 912559, 912559, 912559, 912559, 912559, 912559, 912559, 912559, 64206])
INFO:unittestLogger:Executing test setup...
INFO:unittestLogger:Test setup complete. Executing test...
INFO:unittestLogger:Test execution complete. Running cleanup...
ERROR:unittestLogger:<Test Result: Test Failed>
INFO:unittestLogger:Executing test setup...
INFO:unittestLogger:Test setup complete. Executing test...
ERROR:unittestLogger:
Traceback (most recent call last):
  File "C:\Users\czhao\git_root\dtaf\czhao_coverage\src\dtaf_core\lib\base_test_case.py", line 195, in main
    test_result = tester.execute()
  File "c:\program files\python38\lib\unittest\mock.py", line 1081, in __call__
    return self._mock_call(*args, **kwargs)
  File "c:\program files\python38\lib\unittest\mock.py", line 1085, in _mock_call
    return self._execute_mock_call(*args, **kwargs)
  File "c:\program files\python38\lib\unittest\mock.py", line 1140, in _execute_mock_call
    raise effect
RuntimeError
INFO:unittestLogger:Test execution complete. Running cleanup...
ERROR:unittestLogger:<Test Result: Test Failed>
INFO:unittestLogger:Executing test setup...
INFO:unittestLogger:Test setup complete. Executing test...
INFO:unittestLogger:Test execution complete. Running cleanup...
INFO:unittestLogger:<Test Result: Test Passed>
INFO:unittestLogger:Executing test setup...
ERROR:unittestLogger:
Traceback (most recent call last):
  File "C:\Users\czhao\git_root\dtaf\czhao_coverage\src\dtaf_core\lib\base_test_case.py", line 182, in main
    tester.prepare()
  File "c:\program files\python38\lib\unittest\mock.py", line 1081, in __call__
    return self._mock_call(*args, **kwargs)
  File "c:\program files\python38\lib\unittest\mock.py", line 1085, in _mock_call
    return self._execute_mock_call(*args, **kwargs)
  File "c:\program files\python38\lib\unittest\mock.py", line 1140, in _execute_mock_call
    raise effect
RuntimeError
INFO:unittestLogger:Test preparation failed. Running cleanup...
ERROR:unittestLogger:<Test Result: Test Failed>
INFO:unittestLogger:Executing test setup...
INFO:unittestLogger:Test setup complete. Executing test...
INFO:unittestLogger:Test execution complete. Running cleanup...
ERROR:unittestLogger:<Test Result: Test Failed>
ERROR:root:Traceback (most recent call last):
  File "C:\Users\czhao\git_root\dtaf\czhao_coverage\src\dtaf_core\providers\internal\ssh_sut_os_provider.py", line 149, in execute
    exec_result = target.run(cmd, hide=True, warn=True, timeout=timeout,
  File "c:\program files\python38\lib\unittest\mock.py", line 1081, in __call__
    return self._mock_call(*args, **kwargs)
  File "c:\program files\python38\lib\unittest\mock.py", line 1085, in _mock_call
    return self._execute_mock_call(*args, **kwargs)
  File "c:\program files\python38\lib\unittest\mock.py", line 1140, in _execute_mock_call
    raise effect
OSError
Traceback (most recent call last):
  File "C:\Users\czhao\git_root\dtaf\czhao_coverage\src\dtaf_core\providers\internal\ssh_sut_os_provider.py", line 149, in execute
    exec_result = target.run(cmd, hide=True, warn=True, timeout=timeout,
  File "c:\program files\python38\lib\unittest\mock.py", line 1081, in __call__
    return self._mock_call(*args, **kwargs)
  File "c:\program files\python38\lib\unittest\mock.py", line 1085, in _mock_call
    return self._execute_mock_call(*args, **kwargs)
  File "c:\program files\python38\lib\unittest\mock.py", line 1140, in _execute_mock_call
    raise effect
OSError
ERROR:root:Traceback (most recent call last):
  File "C:\Users\czhao\git_root\dtaf\czhao_coverage\src\dtaf_core\providers\internal\ssh_sut_os_provider.py", line 149, in execute
    exec_result = target.run(cmd, hide=True, warn=True, timeout=timeout,
  File "c:\program files\python38\lib\unittest\mock.py", line 1081, in __call__
    return self._mock_call(*args, **kwargs)
  File "c:\program files\python38\lib\unittest\mock.py", line 1085, in _mock_call
    return self._execute_mock_call(*args, **kwargs)
  File "c:\program files\python38\lib\unittest\mock.py", line 1140, in _execute_mock_call
    raise effect
RuntimeError
Traceback (most recent call last):
  File "C:\Users\czhao\git_root\dtaf\czhao_coverage\src\dtaf_core\providers\internal\ssh_sut_os_provider.py", line 149, in execute
    exec_result = target.run(cmd, hide=True, warn=True, timeout=timeout,
  File "c:\program files\python38\lib\unittest\mock.py", line 1081, in __call__
    return self._mock_call(*args, **kwargs)
  File "c:\program files\python38\lib\unittest\mock.py", line 1085, in _mock_call
    return self._execute_mock_call(*args, **kwargs)
  File "c:\program files\python38\lib\unittest\mock.py", line 1140, in _execute_mock_call
    raise effect
RuntimeError
ERROR:root:Traceback (most recent call last):
  File "C:\Users\czhao\git_root\dtaf\czhao_coverage\src\dtaf_core\providers\internal\ssh_sut_os_provider.py", line 149, in execute
    exec_result = target.run(cmd, hide=True, warn=True, timeout=timeout,
  File "c:\program files\python38\lib\unittest\mock.py", line 1081, in __call__
    return self._mock_call(*args, **kwargs)
  File "c:\program files\python38\lib\unittest\mock.py", line 1085, in _mock_call
    return self._execute_mock_call(*args, **kwargs)
  File "c:\program files\python38\lib\unittest\mock.py", line 1140, in _execute_mock_call
    raise effect
ArithmeticError
Traceback (most recent call last):
  File "C:\Users\czhao\git_root\dtaf\czhao_coverage\src\dtaf_core\providers\internal\ssh_sut_os_provider.py", line 149, in execute
    exec_result = target.run(cmd, hide=True, warn=True, timeout=timeout,
  File "c:\program files\python38\lib\unittest\mock.py", line 1081, in __call__
    return self._mock_call(*args, **kwargs)
  File "c:\program files\python38\lib\unittest\mock.py", line 1085, in _mock_call
    return self._execute_mock_call(*args, **kwargs)
  File "c:\program files\python38\lib\unittest\mock.py", line 1140, in _execute_mock_call
    raise effect
ArithmeticError
ERROR:root:Traceback (most recent call last):
  File "C:\Users\czhao\git_root\dtaf\czhao_coverage\src\dtaf_core\providers\internal\ssh_sut_os_provider.py", line 149, in execute
    exec_result = target.run(cmd, hide=True, warn=True, timeout=timeout,
  File "c:\program files\python38\lib\unittest\mock.py", line 1081, in __call__
    return self._mock_call(*args, **kwargs)
  File "c:\program files\python38\lib\unittest\mock.py", line 1085, in _mock_call
    return self._execute_mock_call(*args, **kwargs)
  File "c:\program files\python38\lib\unittest\mock.py", line 1140, in _execute_mock_call
    raise effect
ValueError
Traceback (most recent call last):
  File "C:\Users\czhao\git_root\dtaf\czhao_coverage\src\dtaf_core\providers\internal\ssh_sut_os_provider.py", line 149, in execute
    exec_result = target.run(cmd, hide=True, warn=True, timeout=timeout,
  File "c:\program files\python38\lib\unittest\mock.py", line 1081, in __call__
    return self._mock_call(*args, **kwargs)
  File "c:\program files\python38\lib\unittest\mock.py", line 1085, in _mock_call
    return self._execute_mock_call(*args, **kwargs)
  File "c:\program files\python38\lib\unittest\mock.py", line 1140, in _execute_mock_call
    raise effect
ValueError
ERROR:root:Traceback (most recent call last):
  File "C:\Users\czhao\git_root\dtaf\czhao_coverage\src\dtaf_core\providers\internal\ssh_sut_os_provider.py", line 149, in execute
    exec_result = target.run(cmd, hide=True, warn=True, timeout=timeout,
  File "c:\program files\python38\lib\unittest\mock.py", line 1081, in __call__
    return self._mock_call(*args, **kwargs)
  File "c:\program files\python38\lib\unittest\mock.py", line 1085, in _mock_call
    return self._execute_mock_call(*args, **kwargs)
  File "c:\program files\python38\lib\unittest\mock.py", line 1140, in _execute_mock_call
    raise effect
KeyError
Traceback (most recent call last):
  File "C:\Users\czhao\git_root\dtaf\czhao_coverage\src\dtaf_core\providers\internal\ssh_sut_os_provider.py", line 149, in execute
    exec_result = target.run(cmd, hide=True, warn=True, timeout=timeout,
  File "c:\program files\python38\lib\unittest\mock.py", line 1081, in __call__
    return self._mock_call(*args, **kwargs)
  File "c:\program files\python38\lib\unittest\mock.py", line 1085, in _mock_call
    return self._execute_mock_call(*args, **kwargs)
  File "c:\program files\python38\lib\unittest\mock.py", line 1140, in _execute_mock_call
    raise effect
KeyError
ERROR:root:CPUID values were not consistent across threads!
NoneType: None
ERROR:root:CPUID Reg eax Leaf 2 Subleaf None: [912559, 64206, 912559, 64206, 912559, 64206, 912559, 64206, 912559, 64206, 912559, 64206]
NoneType: None
ERROR:root:No MSR values received! Please check the ITP setup.
NoneType: None
ERROR:root:No MSR values received! Please check the ITP setup.
NoneType: None
ERROR:root:Write to memory address 0x100p failed!  Expected 912559 Actual: 3735928559
NoneType: None
ERROR:root:Write to MSR address 6 failed! Expected: 912559 Actual: 64206
NoneType: None
ERROR:root:MSR values were not consistent across threads!
NoneType: None
ERROR:root:MSR 6: [912559, 912559, 912559, 912559, 912559, 912559, 912559, 912559, 912559, 912559, 912559, 912559, 912559, 912559, 912559, 912559, 912559, 912559, 912559, 912559, 912559, 912559, 912559, 64206]
NoneType: None
ERROR:root:Write to MSR address 6 failed! Threads had varying values: ('MSR values were not consistent across threads!', [912559, 912559, 912559, 912559, 912559, 912559, 912559, 912559, 912559, 912559, 912559, 912559, 912559, 912559, 912559, 912559, 912559, 912559, 912559, 912559, 912559, 912559, 912559, 64206])
Traceback (most recent call last):
  File "C:\Users\czhao\git_root\dtaf\czhao_coverage\src\dtaf_core\providers\internal\xdp_silicon_debug_provider.py", line 190, in msr_write
    read_back = self.msr_read(msr_address, thread=thread, squash=True)
  File "C:\Users\czhao\git_root\dtaf\czhao_coverage\src\dtaf_core\providers\internal\xdp_silicon_debug_provider.py", line 173, in msr_read
    raise RegisterInconsistencyException("MSR values were not consistent across threads!", msr_values)
dtaf_core.lib.exceptions.RegisterInconsistencyException: ('MSR values were not consistent across threads!', [912559, 912559, 912559, 912559, 912559, 912559, 912559, 912559, 912559, 912559, 912559, 912559, 912559, 912559, 912559, 912559, 912559, 912559, 912559, 912559, 912559, 912559, 912559, 64206])
ERROR:root:MSR values were not consistent across threads!
NoneType: None
ERROR:root:MSR 6: [912559, 912559, 912559, 912559, 912559, 912559, 912559, 912559, 912559, 912559, 912559, 912559, 912559, 912559, 912559, 912559, 912559, 912559, 912559, 912559, 912559, 912559, 912559, 64206]
NoneType: None
ERROR:root:Write to MSR address 6 failed! Threads had varying values: ('MSR values were not consistent across threads!', [912559, 912559, 912559, 912559, 912559, 912559, 912559, 912559, 912559, 912559, 912559, 912559, 912559, 912559, 912559, 912559, 912559, 912559, 912559, 912559, 912559, 912559, 912559, 64206])
Traceback (most recent call last):
  File "C:\Users\czhao\git_root\dtaf\czhao_coverage\src\dtaf_core\providers\internal\xdp_silicon_debug_provider.py", line 190, in msr_write
    read_back = self.msr_read(msr_address, thread=thread, squash=True)
  File "C:\Users\czhao\git_root\dtaf\czhao_coverage\src\dtaf_core\providers\internal\xdp_silicon_debug_provider.py", line 173, in msr_read
    raise RegisterInconsistencyException("MSR values were not consistent across threads!", msr_values)
dtaf_core.lib.exceptions.RegisterInconsistencyException: ('MSR values were not consistent across threads!', [912559, 912559, 912559, 912559, 912559, 912559, 912559, 912559, 912559, 912559, 912559, 912559, 912559, 912559, 912559, 912559, 912559, 912559, 912559, 912559, 912559, 912559, 912559, 64206])
ERROR:root:MSR values were not consistent across threads!
NoneType: None
ERROR:root:MSR 314: [64206, 912559, 64206, 912559, 64206, 912559, 64206, 912559, 64206, 912559, 64206, 912559, 64206, 912559, 64206, 912559, 64206, 912559, 64206, 912559, 64206, 912559, 64206, 912559]
NoneType: None
ERROR:root:Traceback (most recent call last):
  File "C:\Users\czhao\git_root\dtaf\czhao_coverage\src\dtaf_core\providers\internal\ssh_sut_os_provider.py", line 149, in execute
    exec_result = target.run(cmd, hide=True, warn=True, timeout=timeout,
  File "c:\program files\python38\lib\unittest\mock.py", line 1081, in __call__
    return self._mock_call(*args, **kwargs)
  File "c:\program files\python38\lib\unittest\mock.py", line 1085, in _mock_call
    return self._execute_mock_call(*args, **kwargs)
  File "c:\program files\python38\lib\unittest\mock.py", line 1140, in _execute_mock_call
    raise effect
paramiko.ssh_exception.SSHException
Traceback (most recent call last):
  File "C:\Users\czhao\git_root\dtaf\czhao_coverage\src\dtaf_core\providers\internal\ssh_sut_os_provider.py", line 149, in execute
    exec_result = target.run(cmd, hide=True, warn=True, timeout=timeout,
  File "c:\program files\python38\lib\unittest\mock.py", line 1081, in __call__
    return self._mock_call(*args, **kwargs)
  File "c:\program files\python38\lib\unittest\mock.py", line 1085, in _mock_call
    return self._execute_mock_call(*args, **kwargs)
  File "c:\program files\python38\lib\unittest\mock.py", line 1140, in _execute_mock_call
    raise effect
paramiko.ssh_exception.SSHException
INFO:unittestLogger:Executing test setup...
INFO:unittestLogger:Test setup complete. Executing test...
ERROR:unittestLogger:
Traceback (most recent call last):
  File "C:\Users\czhao\git_root\dtaf\czhao_coverage\src\dtaf_core\lib\base_test_case.py", line 195, in main
    test_result = tester.execute()
  File "c:\program files\python38\lib\unittest\mock.py", line 1081, in __call__
    return self._mock_call(*args, **kwargs)
  File "c:\program files\python38\lib\unittest\mock.py", line 1085, in _mock_call
    return self._execute_mock_call(*args, **kwargs)
  File "c:\program files\python38\lib\unittest\mock.py", line 1140, in _execute_mock_call
    raise effect
RuntimeError
INFO:unittestLogger:Test execution complete. Running cleanup...
ERROR:unittestLogger:<Test Result: Test Failed>
INFO:unittestLogger:Executing test setup...
ERROR:unittestLogger:
Traceback (most recent call last):
  File "C:\Users\czhao\git_root\dtaf\czhao_coverage\src\dtaf_core\lib\base_test_case.py", line 182, in main
    tester.prepare()
  File "c:\program files\python38\lib\unittest\mock.py", line 1081, in __call__
    return self._mock_call(*args, **kwargs)
  File "c:\program files\python38\lib\unittest\mock.py", line 1085, in _mock_call
    return self._execute_mock_call(*args, **kwargs)
  File "c:\program files\python38\lib\unittest\mock.py", line 1140, in _execute_mock_call
    raise effect
RuntimeError
INFO:unittestLogger:Test preparation failed. Running cleanup...
ERROR:unittestLogger:<Test Result: Test Failed>
INFO:unittestLogger:Executing test setup...
INFO:unittestLogger:Test setup complete. Executing test...
INFO:unittestLogger:Test execution complete. Running cleanup...
INFO:unittestLogger:<Test Result: Test Passed>
INFO:unittestLogger:Executing test setup...
INFO:unittestLogger:Test setup complete. Executing test...
INFO:unittestLogger:Test execution complete. Running cleanup...
ERROR:unittestLogger:<Test Result: Test Failed>
INFO:unittestLogger:Executing test setup...
INFO:unittestLogger:Test setup complete. Executing test...
INFO:unittestLogger:Test execution complete. Running cleanup...
ERROR:unittestLogger:<Test Result: Test Failed>
ERROR:root:Traceback (most recent call last):
  File "C:\Users\czhao\git_root\dtaf\czhao_coverage\src\dtaf_core\providers\internal\ssh_sut_os_provider.py", line 149, in execute
    exec_result = target.run(cmd, hide=True, warn=True, timeout=timeout,
  File "c:\program files\python38\lib\unittest\mock.py", line 1081, in __call__
    return self._mock_call(*args, **kwargs)
  File "c:\program files\python38\lib\unittest\mock.py", line 1085, in _mock_call
    return self._execute_mock_call(*args, **kwargs)
  File "c:\program files\python38\lib\unittest\mock.py", line 1140, in _execute_mock_call
    raise effect
paramiko.ssh_exception.SSHException
Traceback (most recent call last):
  File "C:\Users\czhao\git_root\dtaf\czhao_coverage\src\dtaf_core\providers\internal\ssh_sut_os_provider.py", line 149, in execute
    exec_result = target.run(cmd, hide=True, warn=True, timeout=timeout,
  File "c:\program files\python38\lib\unittest\mock.py", line 1081, in __call__
    return self._mock_call(*args, **kwargs)
  File "c:\program files\python38\lib\unittest\mock.py", line 1085, in _mock_call
    return self._execute_mock_call(*args, **kwargs)
  File "c:\program files\python38\lib\unittest\mock.py", line 1140, in _execute_mock_call
    raise effect
paramiko.ssh_exception.SSHException
ERROR:root:Traceback (most recent call last):
  File "C:\Users\czhao\git_root\dtaf\czhao_coverage\src\dtaf_core\providers\internal\ssh_sut_os_provider.py", line 149, in execute
    exec_result = target.run(cmd, hide=True, warn=True, timeout=timeout,
  File "c:\program files\python38\lib\unittest\mock.py", line 1081, in __call__
    return self._mock_call(*args, **kwargs)
  File "c:\program files\python38\lib\unittest\mock.py", line 1085, in _mock_call
    return self._execute_mock_call(*args, **kwargs)
  File "c:\program files\python38\lib\unittest\mock.py", line 1140, in _execute_mock_call
    raise effect
OSError
Traceback (most recent call last):
  File "C:\Users\czhao\git_root\dtaf\czhao_coverage\src\dtaf_core\providers\internal\ssh_sut_os_provider.py", line 149, in execute
    exec_result = target.run(cmd, hide=True, warn=True, timeout=timeout,
  File "c:\program files\python38\lib\unittest\mock.py", line 1081, in __call__
    return self._mock_call(*args, **kwargs)
  File "c:\program files\python38\lib\unittest\mock.py", line 1085, in _mock_call
    return self._execute_mock_call(*args, **kwargs)
  File "c:\program files\python38\lib\unittest\mock.py", line 1140, in _execute_mock_call
    raise effect
OSError
ERROR:root:Traceback (most recent call last):
  File "C:\Users\czhao\git_root\dtaf\czhao_coverage\src\dtaf_core\providers\internal\ssh_sut_os_provider.py", line 149, in execute
    exec_result = target.run(cmd, hide=True, warn=True, timeout=timeout,
  File "c:\program files\python38\lib\unittest\mock.py", line 1081, in __call__
    return self._mock_call(*args, **kwargs)
  File "c:\program files\python38\lib\unittest\mock.py", line 1085, in _mock_call
    return self._execute_mock_call(*args, **kwargs)
  File "c:\program files\python38\lib\unittest\mock.py", line 1140, in _execute_mock_call
    raise effect
RuntimeError
Traceback (most recent call last):
  File "C:\Users\czhao\git_root\dtaf\czhao_coverage\src\dtaf_core\providers\internal\ssh_sut_os_provider.py", line 149, in execute
    exec_result = target.run(cmd, hide=True, warn=True, timeout=timeout,
  File "c:\program files\python38\lib\unittest\mock.py", line 1081, in __call__
    return self._mock_call(*args, **kwargs)
  File "c:\program files\python38\lib\unittest\mock.py", line 1085, in _mock_call
    return self._execute_mock_call(*args, **kwargs)
  File "c:\program files\python38\lib\unittest\mock.py", line 1140, in _execute_mock_call
    raise effect
RuntimeError
ERROR:root:Traceback (most recent call last):
  File "C:\Users\czhao\git_root\dtaf\czhao_coverage\src\dtaf_core\providers\internal\ssh_sut_os_provider.py", line 149, in execute
    exec_result = target.run(cmd, hide=True, warn=True, timeout=timeout,
  File "c:\program files\python38\lib\unittest\mock.py", line 1081, in __call__
    return self._mock_call(*args, **kwargs)
  File "c:\program files\python38\lib\unittest\mock.py", line 1085, in _mock_call
    return self._execute_mock_call(*args, **kwargs)
  File "c:\program files\python38\lib\unittest\mock.py", line 1140, in _execute_mock_call
    raise effect
ArithmeticError
Traceback (most recent call last):
  File "C:\Users\czhao\git_root\dtaf\czhao_coverage\src\dtaf_core\providers\internal\ssh_sut_os_provider.py", line 149, in execute
    exec_result = target.run(cmd, hide=True, warn=True, timeout=timeout,
  File "c:\program files\python38\lib\unittest\mock.py", line 1081, in __call__
    return self._mock_call(*args, **kwargs)
  File "c:\program files\python38\lib\unittest\mock.py", line 1085, in _mock_call
    return self._execute_mock_call(*args, **kwargs)
  File "c:\program files\python38\lib\unittest\mock.py", line 1140, in _execute_mock_call
    raise effect
ArithmeticError
ERROR:root:Traceback (most recent call last):
  File "C:\Users\czhao\git_root\dtaf\czhao_coverage\src\dtaf_core\providers\internal\ssh_sut_os_provider.py", line 149, in execute
    exec_result = target.run(cmd, hide=True, warn=True, timeout=timeout,
  File "c:\program files\python38\lib\unittest\mock.py", line 1081, in __call__
    return self._mock_call(*args, **kwargs)
  File "c:\program files\python38\lib\unittest\mock.py", line 1085, in _mock_call
    return self._execute_mock_call(*args, **kwargs)
  File "c:\program files\python38\lib\unittest\mock.py", line 1140, in _execute_mock_call
    raise effect
ValueError
Traceback (most recent call last):
  File "C:\Users\czhao\git_root\dtaf\czhao_coverage\src\dtaf_core\providers\internal\ssh_sut_os_provider.py", line 149, in execute
    exec_result = target.run(cmd, hide=True, warn=True, timeout=timeout,
  File "c:\program files\python38\lib\unittest\mock.py", line 1081, in __call__
    return self._mock_call(*args, **kwargs)
  File "c:\program files\python38\lib\unittest\mock.py", line 1085, in _mock_call
    return self._execute_mock_call(*args, **kwargs)
  File "c:\program files\python38\lib\unittest\mock.py", line 1140, in _execute_mock_call
    raise effect
ValueError
ERROR:root:Traceback (most recent call last):
  File "C:\Users\czhao\git_root\dtaf\czhao_coverage\src\dtaf_core\providers\internal\ssh_sut_os_provider.py", line 149, in execute
    exec_result = target.run(cmd, hide=True, warn=True, timeout=timeout,
  File "c:\program files\python38\lib\unittest\mock.py", line 1081, in __call__
    return self._mock_call(*args, **kwargs)
  File "c:\program files\python38\lib\unittest\mock.py", line 1085, in _mock_call
    return self._execute_mock_call(*args, **kwargs)
  File "c:\program files\python38\lib\unittest\mock.py", line 1140, in _execute_mock_call
    raise effect
KeyError
Traceback (most recent call last):
  File "C:\Users\czhao\git_root\dtaf\czhao_coverage\src\dtaf_core\providers\internal\ssh_sut_os_provider.py", line 149, in execute
    exec_result = target.run(cmd, hide=True, warn=True, timeout=timeout,
  File "c:\program files\python38\lib\unittest\mock.py", line 1081, in __call__
    return self._mock_call(*args, **kwargs)
  File "c:\program files\python38\lib\unittest\mock.py", line 1085, in _mock_call
    return self._execute_mock_call(*args, **kwargs)
  File "c:\program files\python38\lib\unittest\mock.py", line 1140, in _execute_mock_call
    raise effect
KeyError
ERROR:root:CPUID values were not consistent across threads!
NoneType: None
ERROR:root:CPUID Reg eax Leaf 2 Subleaf None: [912559, 64206, 912559, 64206, 912559, 64206, 912559, 64206, 912559, 64206, 912559, 64206]
NoneType: None
ERROR:root:Write to memory address 0x100p failed!  Expected 912559 Actual: 3735928559
NoneType: None
ERROR:root:No MSR values received! Please check the ITP setup.
NoneType: None
ERROR:root:No MSR values received! Please check the ITP setup.
NoneType: None
ERROR:root:MSR values were not consistent across threads!
NoneType: None
ERROR:root:MSR 314: [64206, 912559, 64206, 912559, 64206, 912559, 64206, 912559, 64206, 912559, 64206, 912559, 64206, 912559, 64206, 912559, 64206, 912559, 64206, 912559, 64206, 912559, 64206, 912559]
NoneType: None
ERROR:root:MSR values were not consistent across threads!
NoneType: None
ERROR:root:MSR 6: [912559, 912559, 912559, 912559, 912559, 912559, 912559, 912559, 912559, 912559, 912559, 912559, 912559, 912559, 912559, 912559, 912559, 912559, 912559, 912559, 912559, 912559, 912559, 64206]
NoneType: None
ERROR:root:Write to MSR address 6 failed! Threads had varying values: ('MSR values were not consistent across threads!', [912559, 912559, 912559, 912559, 912559, 912559, 912559, 912559, 912559, 912559, 912559, 912559, 912559, 912559, 912559, 912559, 912559, 912559, 912559, 912559, 912559, 912559, 912559, 64206])
Traceback (most recent call last):
  File "C:\Users\czhao\git_root\dtaf\czhao_coverage\src\dtaf_core\providers\internal\xdp_silicon_debug_provider.py", line 190, in msr_write
    read_back = self.msr_read(msr_address, thread=thread, squash=True)
  File "C:\Users\czhao\git_root\dtaf\czhao_coverage\src\dtaf_core\providers\internal\xdp_silicon_debug_provider.py", line 173, in msr_read
    raise RegisterInconsistencyException("MSR values were not consistent across threads!", msr_values)
dtaf_core.lib.exceptions.RegisterInconsistencyException: ('MSR values were not consistent across threads!', [912559, 912559, 912559, 912559, 912559, 912559, 912559, 912559, 912559, 912559, 912559, 912559, 912559, 912559, 912559, 912559, 912559, 912559, 912559, 912559, 912559, 912559, 912559, 64206])
ERROR:root:MSR values were not consistent across threads!
NoneType: None
ERROR:root:MSR 6: [912559, 912559, 912559, 912559, 912559, 912559, 912559, 912559, 912559, 912559, 912559, 912559, 912559, 912559, 912559, 912559, 912559, 912559, 912559, 912559, 912559, 912559, 912559, 64206]
NoneType: None
ERROR:root:Write to MSR address 6 failed! Threads had varying values: ('MSR values were not consistent across threads!', [912559, 912559, 912559, 912559, 912559, 912559, 912559, 912559, 912559, 912559, 912559, 912559, 912559, 912559, 912559, 912559, 912559, 912559, 912559, 912559, 912559, 912559, 912559, 64206])
Traceback (most recent call last):
  File "C:\Users\czhao\git_root\dtaf\czhao_coverage\src\dtaf_core\providers\internal\xdp_silicon_debug_provider.py", line 190, in msr_write
    read_back = self.msr_read(msr_address, thread=thread, squash=True)
  File "C:\Users\czhao\git_root\dtaf\czhao_coverage\src\dtaf_core\providers\internal\xdp_silicon_debug_provider.py", line 173, in msr_read
    raise RegisterInconsistencyException("MSR values were not consistent across threads!", msr_values)
dtaf_core.lib.exceptions.RegisterInconsistencyException: ('MSR values were not consistent across threads!', [912559, 912559, 912559, 912559, 912559, 912559, 912559, 912559, 912559, 912559, 912559, 912559, 912559, 912559, 912559, 912559, 912559, 912559, 912559, 912559, 912559, 912559, 912559, 64206])
ERROR:root:Write to MSR address 6 failed! Expected: 912559 Actual: 64206
NoneType: None
INFO:unittestLogger:Executing test setup...
INFO:unittestLogger:Test setup complete. Executing test...
INFO:unittestLogger:Test execution complete. Running cleanup...
ERROR:unittestLogger:<Test Result: Test Failed>
INFO:unittestLogger:Executing test setup...
INFO:unittestLogger:Test setup complete. Executing test...
ERROR:unittestLogger:
Traceback (most recent call last):
  File "C:\Users\czhao\git_root\dtaf\czhao_coverage\src\dtaf_core\lib\base_test_case.py", line 195, in main
    test_result = tester.execute()
  File "c:\program files\python38\lib\unittest\mock.py", line 1081, in __call__
    return self._mock_call(*args, **kwargs)
  File "c:\program files\python38\lib\unittest\mock.py", line 1085, in _mock_call
    return self._execute_mock_call(*args, **kwargs)
  File "c:\program files\python38\lib\unittest\mock.py", line 1140, in _execute_mock_call
    raise effect
RuntimeError
INFO:unittestLogger:Test execution complete. Running cleanup...
ERROR:unittestLogger:<Test Result: Test Failed>
INFO:unittestLogger:Executing test setup...
INFO:unittestLogger:Test setup complete. Executing test...
INFO:unittestLogger:Test execution complete. Running cleanup...
ERROR:unittestLogger:<Test Result: Test Failed>
INFO:unittestLogger:Executing test setup...
INFO:unittestLogger:Test setup complete. Executing test...
INFO:unittestLogger:Test execution complete. Running cleanup...
INFO:unittestLogger:<Test Result: Test Passed>
INFO:unittestLogger:Executing test setup...
ERROR:unittestLogger:
Traceback (most recent call last):
  File "C:\Users\czhao\git_root\dtaf\czhao_coverage\src\dtaf_core\lib\base_test_case.py", line 182, in main
    tester.prepare()
  File "c:\program files\python38\lib\unittest\mock.py", line 1081, in __call__
    return self._mock_call(*args, **kwargs)
  File "c:\program files\python38\lib\unittest\mock.py", line 1085, in _mock_call
    return self._execute_mock_call(*args, **kwargs)
  File "c:\program files\python38\lib\unittest\mock.py", line 1140, in _execute_mock_call
    raise effect
RuntimeError
INFO:unittestLogger:Test preparation failed. Running cleanup...
ERROR:unittestLogger:<Test Result: Test Failed>
ERROR:root:Traceback (most recent call last):
  File "C:\Users\czhao\git_root\dtaf\czhao_coverage\src\dtaf_core\providers\internal\ssh_sut_os_provider.py", line 149, in execute
    exec_result = target.run(cmd, hide=True, warn=True, timeout=timeout,
  File "c:\program files\python38\lib\unittest\mock.py", line 1081, in __call__
    return self._mock_call(*args, **kwargs)
  File "c:\program files\python38\lib\unittest\mock.py", line 1085, in _mock_call
    return self._execute_mock_call(*args, **kwargs)
  File "c:\program files\python38\lib\unittest\mock.py", line 1140, in _execute_mock_call
    raise effect
paramiko.ssh_exception.SSHException
Traceback (most recent call last):
  File "C:\Users\czhao\git_root\dtaf\czhao_coverage\src\dtaf_core\providers\internal\ssh_sut_os_provider.py", line 149, in execute
    exec_result = target.run(cmd, hide=True, warn=True, timeout=timeout,
  File "c:\program files\python38\lib\unittest\mock.py", line 1081, in __call__
    return self._mock_call(*args, **kwargs)
  File "c:\program files\python38\lib\unittest\mock.py", line 1085, in _mock_call
    return self._execute_mock_call(*args, **kwargs)
  File "c:\program files\python38\lib\unittest\mock.py", line 1140, in _execute_mock_call
    raise effect
paramiko.ssh_exception.SSHException
ERROR:root:Traceback (most recent call last):
  File "C:\Users\czhao\git_root\dtaf\czhao_coverage\src\dtaf_core\providers\internal\ssh_sut_os_provider.py", line 149, in execute
    exec_result = target.run(cmd, hide=True, warn=True, timeout=timeout,
  File "c:\program files\python38\lib\unittest\mock.py", line 1081, in __call__
    return self._mock_call(*args, **kwargs)
  File "c:\program files\python38\lib\unittest\mock.py", line 1085, in _mock_call
    return self._execute_mock_call(*args, **kwargs)
  File "c:\program files\python38\lib\unittest\mock.py", line 1140, in _execute_mock_call
    raise effect
OSError
Traceback (most recent call last):
  File "C:\Users\czhao\git_root\dtaf\czhao_coverage\src\dtaf_core\providers\internal\ssh_sut_os_provider.py", line 149, in execute
    exec_result = target.run(cmd, hide=True, warn=True, timeout=timeout,
  File "c:\program files\python38\lib\unittest\mock.py", line 1081, in __call__
    return self._mock_call(*args, **kwargs)
  File "c:\program files\python38\lib\unittest\mock.py", line 1085, in _mock_call
    return self._execute_mock_call(*args, **kwargs)
  File "c:\program files\python38\lib\unittest\mock.py", line 1140, in _execute_mock_call
    raise effect
OSError
ERROR:root:Traceback (most recent call last):
  File "C:\Users\czhao\git_root\dtaf\czhao_coverage\src\dtaf_core\providers\internal\ssh_sut_os_provider.py", line 149, in execute
    exec_result = target.run(cmd, hide=True, warn=True, timeout=timeout,
  File "c:\program files\python38\lib\unittest\mock.py", line 1081, in __call__
    return self._mock_call(*args, **kwargs)
  File "c:\program files\python38\lib\unittest\mock.py", line 1085, in _mock_call
    return self._execute_mock_call(*args, **kwargs)
  File "c:\program files\python38\lib\unittest\mock.py", line 1140, in _execute_mock_call
    raise effect
RuntimeError
Traceback (most recent call last):
  File "C:\Users\czhao\git_root\dtaf\czhao_coverage\src\dtaf_core\providers\internal\ssh_sut_os_provider.py", line 149, in execute
    exec_result = target.run(cmd, hide=True, warn=True, timeout=timeout,
  File "c:\program files\python38\lib\unittest\mock.py", line 1081, in __call__
    return self._mock_call(*args, **kwargs)
  File "c:\program files\python38\lib\unittest\mock.py", line 1085, in _mock_call
    return self._execute_mock_call(*args, **kwargs)
  File "c:\program files\python38\lib\unittest\mock.py", line 1140, in _execute_mock_call
    raise effect
RuntimeError
ERROR:root:Traceback (most recent call last):
  File "C:\Users\czhao\git_root\dtaf\czhao_coverage\src\dtaf_core\providers\internal\ssh_sut_os_provider.py", line 149, in execute
    exec_result = target.run(cmd, hide=True, warn=True, timeout=timeout,
  File "c:\program files\python38\lib\unittest\mock.py", line 1081, in __call__
    return self._mock_call(*args, **kwargs)
  File "c:\program files\python38\lib\unittest\mock.py", line 1085, in _mock_call
    return self._execute_mock_call(*args, **kwargs)
  File "c:\program files\python38\lib\unittest\mock.py", line 1140, in _execute_mock_call
    raise effect
ArithmeticError
Traceback (most recent call last):
  File "C:\Users\czhao\git_root\dtaf\czhao_coverage\src\dtaf_core\providers\internal\ssh_sut_os_provider.py", line 149, in execute
    exec_result = target.run(cmd, hide=True, warn=True, timeout=timeout,
  File "c:\program files\python38\lib\unittest\mock.py", line 1081, in __call__
    return self._mock_call(*args, **kwargs)
  File "c:\program files\python38\lib\unittest\mock.py", line 1085, in _mock_call
    return self._execute_mock_call(*args, **kwargs)
  File "c:\program files\python38\lib\unittest\mock.py", line 1140, in _execute_mock_call
    raise effect
ArithmeticError
ERROR:root:Traceback (most recent call last):
  File "C:\Users\czhao\git_root\dtaf\czhao_coverage\src\dtaf_core\providers\internal\ssh_sut_os_provider.py", line 149, in execute
    exec_result = target.run(cmd, hide=True, warn=True, timeout=timeout,
  File "c:\program files\python38\lib\unittest\mock.py", line 1081, in __call__
    return self._mock_call(*args, **kwargs)
  File "c:\program files\python38\lib\unittest\mock.py", line 1085, in _mock_call
    return self._execute_mock_call(*args, **kwargs)
  File "c:\program files\python38\lib\unittest\mock.py", line 1140, in _execute_mock_call
    raise effect
ValueError
Traceback (most recent call last):
  File "C:\Users\czhao\git_root\dtaf\czhao_coverage\src\dtaf_core\providers\internal\ssh_sut_os_provider.py", line 149, in execute
    exec_result = target.run(cmd, hide=True, warn=True, timeout=timeout,
  File "c:\program files\python38\lib\unittest\mock.py", line 1081, in __call__
    return self._mock_call(*args, **kwargs)
  File "c:\program files\python38\lib\unittest\mock.py", line 1085, in _mock_call
    return self._execute_mock_call(*args, **kwargs)
  File "c:\program files\python38\lib\unittest\mock.py", line 1140, in _execute_mock_call
    raise effect
ValueError
ERROR:root:Traceback (most recent call last):
  File "C:\Users\czhao\git_root\dtaf\czhao_coverage\src\dtaf_core\providers\internal\ssh_sut_os_provider.py", line 149, in execute
    exec_result = target.run(cmd, hide=True, warn=True, timeout=timeout,
  File "c:\program files\python38\lib\unittest\mock.py", line 1081, in __call__
    return self._mock_call(*args, **kwargs)
  File "c:\program files\python38\lib\unittest\mock.py", line 1085, in _mock_call
    return self._execute_mock_call(*args, **kwargs)
  File "c:\program files\python38\lib\unittest\mock.py", line 1140, in _execute_mock_call
    raise effect
KeyError
Traceback (most recent call last):
  File "C:\Users\czhao\git_root\dtaf\czhao_coverage\src\dtaf_core\providers\internal\ssh_sut_os_provider.py", line 149, in execute
    exec_result = target.run(cmd, hide=True, warn=True, timeout=timeout,
  File "c:\program files\python38\lib\unittest\mock.py", line 1081, in __call__
    return self._mock_call(*args, **kwargs)
  File "c:\program files\python38\lib\unittest\mock.py", line 1085, in _mock_call
    return self._execute_mock_call(*args, **kwargs)
  File "c:\program files\python38\lib\unittest\mock.py", line 1140, in _execute_mock_call
    raise effect
KeyError
ERROR:root:CPUID values were not consistent across threads!
NoneType: None
ERROR:root:CPUID Reg eax Leaf 2 Subleaf None: [912559, 64206, 912559, 64206, 912559, 64206, 912559, 64206, 912559, 64206, 912559, 64206]
NoneType: None
ERROR:root:Write to memory address 0x100p failed!  Expected 912559 Actual: 3735928559
NoneType: None
ERROR:root:No MSR values received! Please check the ITP setup.
NoneType: None
ERROR:root:No MSR values received! Please check the ITP setup.
NoneType: None
ERROR:root:MSR values were not consistent across threads!
NoneType: None
ERROR:root:MSR 314: [64206, 912559, 64206, 912559, 64206, 912559, 64206, 912559, 64206, 912559, 64206, 912559, 64206, 912559, 64206, 912559, 64206, 912559, 64206, 912559, 64206, 912559, 64206, 912559]
NoneType: None
ERROR:root:MSR values were not consistent across threads!
NoneType: None
ERROR:root:MSR 6: [912559, 912559, 912559, 912559, 912559, 912559, 912559, 912559, 912559, 912559, 912559, 912559, 912559, 912559, 912559, 912559, 912559, 912559, 912559, 912559, 912559, 912559, 912559, 64206]
NoneType: None
ERROR:root:Write to MSR address 6 failed! Threads had varying values: ('MSR values were not consistent across threads!', [912559, 912559, 912559, 912559, 912559, 912559, 912559, 912559, 912559, 912559, 912559, 912559, 912559, 912559, 912559, 912559, 912559, 912559, 912559, 912559, 912559, 912559, 912559, 64206])
Traceback (most recent call last):
  File "C:\Users\czhao\git_root\dtaf\czhao_coverage\src\dtaf_core\providers\internal\xdp_silicon_debug_provider.py", line 190, in msr_write
    read_back = self.msr_read(msr_address, thread=thread, squash=True)
  File "C:\Users\czhao\git_root\dtaf\czhao_coverage\src\dtaf_core\providers\internal\xdp_silicon_debug_provider.py", line 173, in msr_read
    raise RegisterInconsistencyException("MSR values were not consistent across threads!", msr_values)
dtaf_core.lib.exceptions.RegisterInconsistencyException: ('MSR values were not consistent across threads!', [912559, 912559, 912559, 912559, 912559, 912559, 912559, 912559, 912559, 912559, 912559, 912559, 912559, 912559, 912559, 912559, 912559, 912559, 912559, 912559, 912559, 912559, 912559, 64206])
ERROR:root:MSR values were not consistent across threads!
NoneType: None
ERROR:root:MSR 6: [912559, 912559, 912559, 912559, 912559, 912559, 912559, 912559, 912559, 912559, 912559, 912559, 912559, 912559, 912559, 912559, 912559, 912559, 912559, 912559, 912559, 912559, 912559, 64206]
NoneType: None
ERROR:root:Write to MSR address 6 failed! Threads had varying values: ('MSR values were not consistent across threads!', [912559, 912559, 912559, 912559, 912559, 912559, 912559, 912559, 912559, 912559, 912559, 912559, 912559, 912559, 912559, 912559, 912559, 912559, 912559, 912559, 912559, 912559, 912559, 64206])
Traceback (most recent call last):
  File "C:\Users\czhao\git_root\dtaf\czhao_coverage\src\dtaf_core\providers\internal\xdp_silicon_debug_provider.py", line 190, in msr_write
    read_back = self.msr_read(msr_address, thread=thread, squash=True)
  File "C:\Users\czhao\git_root\dtaf\czhao_coverage\src\dtaf_core\providers\internal\xdp_silicon_debug_provider.py", line 173, in msr_read
    raise RegisterInconsistencyException("MSR values were not consistent across threads!", msr_values)
dtaf_core.lib.exceptions.RegisterInconsistencyException: ('MSR values were not consistent across threads!', [912559, 912559, 912559, 912559, 912559, 912559, 912559, 912559, 912559, 912559, 912559, 912559, 912559, 912559, 912559, 912559, 912559, 912559, 912559, 912559, 912559, 912559, 912559, 64206])
ERROR:root:Write to MSR address 6 failed! Expected: 912559 Actual: 64206
NoneType: None

